Workbook

Sheet 📋 Test Plan Summary
B2: EAM Platform — Phase 0 Foundations Test Plan & Execution Tracker
B9: Project | E9: Enterprise Asset Management (EAM) Web Application
B10: Phase | E10: Phase 0 — Foundations
B11: Document | E11: Test Plan v1.0
B12: Prepared by | E12: QA Team
B13: Date | E13: 23 May 2026
B14: Total Tests | E14: =COUNTA('🔐 P0-1 Identity'!B5:B500)+COUNTA('⚙️ P0-2 Config Engine'!B5:B500)+COUNTA('🔄 P0-3 Workflow'!B5:B500)+COUNTA('🔌 P0-4 Integration'!B5:B500)+COUNTA('📎 P0-5 Attachments'!B5:B500)+COUNTA('📊 P0-6 Reporting'!B5:B500)+COUNTA('🖥️ P0-7 Dashboard'!B5:B500)+COUNTA('📧 P0-8 Notifications'!B5:B500)+COUNTA('🧩 Integration Sprint'!B5:B500) -> 166
B17: Status Legend
B18: ⬜ NOT RUN | D18: ✅ PASS | F18: ❌ FAIL | H18: ⏭️ SKIP | J18: 🔄 IN PROGRESS | L18: 🚫 BLOCKED
B21: Workstream | C21: Ref | D21: Total Tests | E21: Pass | F21: Fail | G21: Skip | H21: Not Run | I21: Pass % | J21: Status
B22: P0-1 User Management & Identity | C22: P0-1 | D22: =COUNTA('🔐 P0-1 Identity'!B5:B500) -> 26 | E22: =COUNTIF('🔐 P0-1 Identity'!G5:G500,"✅ PASS") -> 0 | F22: =COUNTIF('🔐 P0-1 Identity'!G5:G500,"❌ FAIL") -> 0 | G22: =COUNTIF('🔐 P0-1 Identity'!G5:G500,"⏭️ SKIP") -> 0 | H22: =COUNTIF('🔐 P0-1 Identity'!G5:G500,"⬜ NOT RUN") -> 26 | J22: =IF(D22=0,0,E22/D22) -> 0 | K22: =IF(F22>0,"❌ FAIL",IF(H22>0,"⬜ NOT RUN","✅ PASS")) -> ⬜ NOT RUN
B23: P0-2 Application Configuration Engine | C23: P0-2 | D23: =COUNTA('⚙️ P0-2 Config Engine'!B5:B500) -> 19 | E23: =COUNTIF('⚙️ P0-2 Config Engine'!G5:G500,"✅ PASS") -> 0 | F23: =COUNTIF('⚙️ P0-2 Config Engine'!G5:G500,"❌ FAIL") -> 0 | G23: =COUNTIF('⚙️ P0-2 Config Engine'!G5:G500,"⏭️ SKIP") -> 0 | H23: =COUNTIF('⚙️ P0-2 Config Engine'!G5:G500,"⬜ NOT RUN") -> 19 | J23: =IF(D23=0,0,E23/D23) -> 0 | K23: =IF(F23>0,"❌ FAIL",IF(H23>0,"⬜ NOT RUN","✅ PASS")) -> ⬜ NOT RUN
B24: P0-3 Schema Extension & Workflow Builder | C24: P0-3 | D24: =COUNTA('🔄 P0-3 Workflow'!B5:B500) -> 18 | E24: =COUNTIF('🔄 P0-3 Workflow'!G5:G500,"✅ PASS") -> 0 | F24: =COUNTIF('🔄 P0-3 Workflow'!G5:G500,"❌ FAIL") -> 0 | G24: =COUNTIF('🔄 P0-3 Workflow'!G5:G500,"⏭️ SKIP") -> 0 | H24: =COUNTIF('🔄 P0-3 Workflow'!G5:G500,"⬜ NOT RUN") -> 18 | J24: =IF(D24=0,0,E24/D24) -> 0 | K24: =IF(F24>0,"❌ FAIL",IF(H24>0,"⬜ NOT RUN","✅ PASS")) -> ⬜ NOT RUN
B25: P0-4 Integration Framework | C25: P0-4 | D25: =COUNTA('🔌 P0-4 Integration'!B5:B500) -> 13 | E25: =COUNTIF('🔌 P0-4 Integration'!G5:G500,"✅ PASS") -> 0 | F25: =COUNTIF('🔌 P0-4 Integration'!G5:G500,"❌ FAIL") -> 0 | G25: =COUNTIF('🔌 P0-4 Integration'!G5:G500,"⏭️ SKIP") -> 0 | H25: =COUNTIF('🔌 P0-4 Integration'!G5:G500,"⬜ NOT RUN") -> 13 | J25: =IF(D25=0,0,E25/D25) -> 0 | K25: =IF(F25>0,"❌ FAIL",IF(H25>0,"⬜ NOT RUN","✅ PASS")) -> ⬜ NOT RUN
B26: P0-5 Attachment Service + Virus Scan | C26: P0-5 | D26: =COUNTA('📎 P0-5 Attachments'!B5:B500) -> 13 | E26: =COUNTIF('📎 P0-5 Attachments'!G5:G500,"✅ PASS") -> 0 | F26: =COUNTIF('📎 P0-5 Attachments'!G5:G500,"❌ FAIL") -> 0 | G26: =COUNTIF('📎 P0-5 Attachments'!G5:G500,"⏭️ SKIP") -> 0 | H26: =COUNTIF('📎 P0-5 Attachments'!G5:G500,"⬜ NOT RUN") -> 13 | J26: =IF(D26=0,0,E26/D26) -> 0 | K26: =IF(F26>0,"❌ FAIL",IF(H26>0,"⬜ NOT RUN","✅ PASS")) -> ⬜ NOT RUN
B27: P0-6 Reporting Engine & BI Adapters | C27: P0-6 | D27: =COUNTA('📊 P0-6 Reporting'!B5:B500) -> 14 | E27: =COUNTIF('📊 P0-6 Reporting'!G5:G500,"✅ PASS") -> 0 | F27: =COUNTIF('📊 P0-6 Reporting'!G5:G500,"❌ FAIL") -> 0 | G27: =COUNTIF('📊 P0-6 Reporting'!G5:G500,"⏭️ SKIP") -> 0 | H27: =COUNTIF('📊 P0-6 Reporting'!G5:G500,"⬜ NOT RUN") -> 14 | J27: =IF(D27=0,0,E27/D27) -> 0 | K27: =IF(F27>0,"❌ FAIL",IF(H27>0,"⬜ NOT RUN","✅ PASS")) -> ⬜ NOT RUN
B28: P0-7 Dashboard & Collaboration | C28: P0-7 | D28: =COUNTA('🖥️ P0-7 Dashboard'!B5:B500) -> 14 | E28: =COUNTIF('🖥️ P0-7 Dashboard'!G5:G500,"✅ PASS") -> 0 | F28: =COUNTIF('🖥️ P0-7 Dashboard'!G5:G500,"❌ FAIL") -> 0 | G28: =COUNTIF('🖥️ P0-7 Dashboard'!G5:G500,"⏭️ SKIP") -> 0 | H28: =COUNTIF('🖥️ P0-7 Dashboard'!G5:G500,"⬜ NOT RUN") -> 14 | J28: =IF(D28=0,0,E28/D28) -> 0 | K28: =IF(F28>0,"❌ FAIL",IF(H28>0,"⬜ NOT RUN","✅ PASS")) -> ⬜ NOT RUN
B29: P0-8 Email Notification Framework | C29: P0-8 | D29: =COUNTA('📧 P0-8 Notifications'!B5:B500) -> 16 | E29: =COUNTIF('📧 P0-8 Notifications'!G5:G500,"✅ PASS") -> 0 | F29: =COUNTIF('📧 P0-8 Notifications'!G5:G500,"❌ FAIL") -> 0 | G29: =COUNTIF('📧 P0-8 Notifications'!G5:G500,"⏭️ SKIP") -> 0 | H29: =COUNTIF('📧 P0-8 Notifications'!G5:G500,"⬜ NOT RUN") -> 16 | J29: =IF(D29=0,0,E29/D29) -> 0 | K29: =IF(F29>0,"❌ FAIL",IF(H29>0,"⬜ NOT RUN","✅ PASS")) -> ⬜ NOT RUN
B30: Integration Sprint | C30: INT | D30: =COUNTA('🧩 Integration Sprint'!B5:B500) -> 33 | E30: =COUNTIF('🧩 Integration Sprint'!G5:G500,"✅ PASS") -> 0 | F30: =COUNTIF('🧩 Integration Sprint'!G5:G500,"❌ FAIL") -> 0 | G30: =COUNTIF('🧩 Integration Sprint'!G5:G500,"⏭️ SKIP") -> 0 | H30: =COUNTIF('🧩 Integration Sprint'!G5:G500,"⬜ NOT RUN") -> 33 | J30: =IF(D30=0,0,E30/D30) -> 0 | K30: =IF(F30>0,"❌ FAIL",IF(H30>0,"⬜ NOT RUN","✅ PASS")) -> ⬜ NOT RUN
B31: TOTALS | D31: =SUM(D22:D30) -> 166 | E31: =SUM(E22:E30) -> 0 | F31: =SUM(F22:F30) -> 0 | G31: =SUM(G22:G30) -> 0 | H31: =SUM(H22:H30) -> 166 | I31: =IF(D31=0,0,E31/D31) -> 0 | J31: =IF(F31>0,"❌ FAIL",IF(H31>0,"⬜ NOT RUN","✅ PASS")) -> ⬜ NOT RUN

Sheet 🔐 P0-1 Identity
A2: EAM Phase 0 — P0-1 User Management & Identity | Test Cases
A3: Workstream: P0-1 • Pass: =COUNTIF(G5:G5000,"✅ PASS") | Fail: =COUNTIF(G5:G5000,"❌ FAIL") | Total: =COUNTA(B5:B5000)
A4: # | B4: Test ID | C4: Category | D4: Type | E4: Priority | F4: Test Title | G4: Status | H4: Preconditions | I4: Test Steps | J4: Expected Result | K4: Actual Result | L4: Tester | M4: Date Tested | N4: Notes / Defect Ref
A5: Local Authentication
A6: 1 | B6: P0-1-U-001 | C6: Local Authentication | D6: Unit | E6: P1-Critical | F6: Password hashing uses Argon2id | G6: ⬜ NOT RUN | H6: packages/auth installed | I6: 1. Call hashPassword('Test@1234') 2. Call verifyPassword('Test@1234', hash) | J6: Hash produced; verify returns true; plain text not stored
A7: 2 | B7: P0-1-U-002 | C7: Local Authentication | D7: Unit | E7: P1-Critical | F7: Password policy enforcement — min length | G7: ⬜ NOT RUN | H7: Policy: minLength=10 | I7: 1. Attempt register with password 'Short1!' | J7: Validation error returned; user not created
A8: 3 | B8: P0-1-U-003 | C8: Local Authentication | D8: Unit | E8: P1-Critical | F8: Password policy — complexity rules | G8: ⬜ NOT RUN | H8: Policy: requireUppercase, requireNumber, requireSpecial | I8: 1. Try 'alllowercase1!' 2. Try 'NoNumber!!' 3. Try 'Valid@Pass1' | J8: First two rejected with specific error; third accepted
A9: 4 | B9: P0-1-U-004 | C9: Local Authentication | D9: Unit | E9: P2-High | F9: Account lockout after N failed logins | G9: ⬜ NOT RUN | H9: lockoutAfterFailures=5 | I9: 1. POST /auth/login with wrong password 5 times 2. Try correct password on 6th attempt | J9: 6th attempt returns 429 with lockout_until timestamp
A10: 5 | B10: P0-1-I-005 | C10: Local Authentication | D10: Integration | E10: P1-Critical | F10: Full register → login → refresh → logout cycle | G10: ⬜ NOT RUN | H10: Postgres running via Testcontainers | I10: 1. POST /auth/register 2. POST /auth/login 3. POST /auth/refresh 4. POST /auth/logout 5. GET /auth/me with old token | J10: Each step returns correct response; step 5 returns 401
A11: 6 | B11: P0-1-I-006 | C11: Local Authentication | D11: Integration | E11: P1-Critical | F11: Refresh token rotation — old token invalidated | G11: ⬜ NOT RUN | H11: Valid session exists | I11: 1. POST /auth/refresh → get new token pair 2. POST /auth/refresh with OLD refresh token | J11: Step 2 returns 401; old token is revoked
A12: 7 | B12: P0-1-I-007 | C12: Local Authentication | D12: Integration | E12: P2-High | F12: Password reset flow end-to-end | G12: ⬜ NOT RUN | H12: SMTP mock (Mailhog) configured | I12: 1. POST /auth/password/reset-request 2. Extract token from email 3. POST /auth/password/reset 4. Login with new password | J12: Login succeeds with new password; old password rejected
A13: Multi-Factor Authentication
A14: 1 | B14: P0-1-M-001 | C14: Multi-Factor Authentication | D14: Integration | E14: P1-Critical | F14: TOTP setup — QR code + verify | G14: ⬜ NOT RUN | H14: User logged in | I14: 1. POST /auth/mfa/setup 2. Generate TOTP code from secret 3. POST /auth/mfa/verify-setup with code | J14: users.mfa_enabled=true; 10 recovery codes returned (plaintext, once)
A15: 2 | B15: P0-1-M-002 | C15: Multi-Factor Authentication | D15: Integration | E15: P1-Critical | F15: MFA login challenge flow | G15: ⬜ NOT RUN | H15: User has MFA enabled | I15: 1. POST /auth/login → expect {mfa_required:true, mfa_session_token} 2. Generate TOTP code 3. POST /auth/mfa/challenge with code + session token | J15: Step 3 returns full JWT pair; mfa_verified=true in JWT claims
A16: 3 | B16: P0-1-M-003 | C16: Multi-Factor Authentication | D16: Integration | E16: P2-High | F16: MFA recovery code usage | G16: ⬜ NOT RUN | H16: User has MFA enabled; has recovery codes | I16: 1. POST /auth/mfa/challenge with valid recovery_code instead of TOTP | J16: Login succeeds; used recovery code marked used_at; cannot be reused
A17: 4 | B17: P0-1-M-004 | C17: Multi-Factor Authentication | D17: Integration | E17: P2-High | F17: Per-role MFA enforcement | G17: ⬜ NOT RUN | H17: Role 'Admin' has require_mfa=true; user in Admin role without MFA enabled | I17: 1. User completes password login (no MFA) 2. Access admin-only endpoint | J17: Step 2 returns 401 with error code MFA_REQUIRED
A18: 5 | B18: P0-1-M-005 | C18: Multi-Factor Authentication | D18: Unit | E18: P3-Medium | F18: MFA secret encrypted at rest | G18: ⬜ NOT RUN | H18: User has MFA enabled | I18: 1. Query users table directly for mfa_secret column | J18: Value is encrypted ciphertext; not plain TOTP secret
A19: AD / LDAP Synchronisation
A20: 1 | B20: P0-1-L-001 | C20: AD / LDAP Synchronisation | D20: Integration | E20: P1-Critical | F20: LDAP user sync creates EAM user | G20: ⬜ NOT RUN | H20: Mock LDAP server running; identity provider configured | I20: 1. Trigger POST /admin/identity-providers/:id/sync 2. Query /admin/users | J20: User from LDAP appears in EAM; auth_source=LDAP; attributes mapped correctly
A21: 2 | B21: P0-1-L-002 | C21: AD / LDAP Synchronisation | D21: Integration | E21: P1-Critical | F21: LDAP group membership synced | G21: ⬜ NOT RUN | H21: Mock LDAP has group 'EAM-Supervisors' with test user | I21: 1. Trigger sync 2. GET /admin/groups | J21: Group created in EAM; user is member; group can be assigned EAM role
A22: 3 | B22: P0-1-L-003 | C22: AD / LDAP Synchronisation | D22: Integration | E22: P2-High | F22: Delta sync — only changed records fetched | G22: ⬜ NOT RUN | H22: Full sync completed; one user modified in LDAP | I22: 1. Modify user attribute in mock LDAP 2. Trigger sync 3. Check audit log | J22: Sync log shows 1 updated (not all users); modifyTimestamp used correctly
A23: 4 | B23: P0-1-L-004 | C23: AD / LDAP Synchronisation | D23: Integration | E23: P2-High | F23: Deactivated LDAP user disabled in EAM | G23: ⬜ NOT RUN | H23: User exists in EAM from previous sync | I23: 1. Remove user from LDAP 2. Trigger sync 3. Attempt login as that user | J23: User.is_active=false; login returns 403
A24: 5 | B24: P0-1-L-005 | C24: AD / LDAP Synchronisation | D24: Integration | E24: P3-Medium | F24: LDAP sync audit log records outcome | G24: ⬜ NOT RUN | H24: After a sync with 3 adds, 1 update | I24: 1. Check audit_logs table after sync | J24: Entry with action=LDAP_SYNC, metadata.added=3, metadata.updated=1
A25: SSO — SAML 2.0 & OIDC
A26: 1 | B26: P0-1-S-001 | C26: SSO — SAML 2.0 & OIDC | D26: E2E | E26: P1-Critical | F26: SAML 2.0 SP-initiated login | G26: ⬜ NOT RUN | H26: Mock SAML IdP running; provider configured in EAM | I26: 1. Navigate to /auth/saml/:id/login 2. Complete mock IdP flow 3. Callback to EAM | J26: User upserted in EAM; JWT session issued; auth_source=SAML
A27: 2 | B27: P0-1-S-002 | C27: SSO — SAML 2.0 & OIDC | D27: E2E | E27: P2-High | F27: OIDC login with PKCE against mock IdP | G27: ⬜ NOT RUN | H27: OIDC provider configured with discovery URL | I27: 1. Navigate to /auth/oidc/:id/login 2. Complete OIDC flow 3. Callback | J27: Tokens exchanged; user info fetched; EAM session issued
A28: 3 | B28: P0-1-S-003 | C28: SSO — SAML 2.0 & OIDC | D28: Integration | E28: P2-High | F28: SSO claim mapping — groups auto-assigned | G28: ⬜ NOT RUN | H28: SAML response includes group attribute 'EAM-Admins' | I28: 1. Login via SAML 2. Check user's groups in EAM | J28: User added to EAM group 'EAM-Admins' automatically
A29: 4 | B29: P0-1-S-004 | C29: SSO — SAML 2.0 & OIDC | D29: API | E29: P3-Medium | F29: Admin can disable SSO provider | G29: ⬜ NOT RUN | H29: Active SSO provider exists | I29: 1. PUT /admin/identity-providers/:id {is_active:false} 2. Try SSO login | J29: SSO login redirects with error; local auth still works
A30: RBAC & User Admin
A31: 1 | B31: P0-1-R-001 | C31: RBAC & User Admin | D31: Integration | E31: P1-Critical | F31: Role assignment grants permissions | G31: ⬜ NOT RUN | H31: User without any role | I31: 1. Create role with permission 'workorders:read' 2. Assign role to user 3. Access GET /workorders | J31: Access granted immediately (within same session via token refresh)
A32: 2 | B32: P0-1-R-002 | C32: RBAC & User Admin | D32: Integration | E32: P1-Critical | F32: Effective permissions — union of multiple roles | G32: ⬜ NOT RUN | H32: User has Role A (read) and Role B (write) | I32: 1. GET /admin/users/:id/effective-permissions | J32: Result includes both read and write permissions
A33: 3 | B33: P0-1-R-003 | C33: RBAC & User Admin | D33: Integration | E33: P2-High | F33: Admin deactivates user — all sessions invalidated | G33: ⬜ NOT RUN | H33: User has 2 active sessions | I33: 1. PUT /admin/users/:id {is_active:false} 2. Make request with both tokens | J33: Both tokens return 401
A34: 4 | B34: P0-1-R-004 | C34: RBAC & User Admin | D34: Security | E34: P1-Critical | F34: Impersonation is audit logged | G34: ⬜ NOT RUN | H34: Admin user with impersonate permission | I34: 1. POST /admin/users/:id/impersonate 2. Perform an action 3. Check audit_logs | J34: audit_logs shows original_admin_id and impersonated_user_id on every action
A35: 5 | B35: P0-1-R-005 | C35: RBAC & User Admin | D35: API | E35: P2-High | F35: Group-based role inheritance | G35: ⬜ NOT RUN | H35: Group assigned role 'Technician' | I35: 1. Add user to group 2. Check user's effective permissions | J35: User inherits all permissions from 'Technician' role via group

Sheet ⚙️ P0-2 Config Engine
A2: EAM Phase 0 — P0-2 Application Configuration Engine | Test Cases
A3: Workstream: P0-2 • Pass: =COUNTIF(G5:G5000,"✅ PASS") | Fail: =COUNTIF(G5:G5000,"❌ FAIL") | Total: =COUNTA(B5:B5000)
A4: # | B4: Test ID | C4: Category | D4: Type | E4: Priority | F4: Test Title | G4: Status | H4: Preconditions | I4: Test Steps | J4: Expected Result | K4: Actual Result | L4: Tester | M4: Date Tested | N4: Notes / Defect Ref
A5: Field Management
A6: 1 | B6: P0-2-F-001 | C6: Field Management | D6: Integration | E6: P1-Critical | F6: Add custom text field to Asset entity | G6: ⬜ NOT RUN | H6: Admin auth token; Asset entity exists | I6: 1. POST /admin/config/entities/Asset/fields {field_key:'asset_tag', field_type:'TEXT', is_required_global:true} 2. GET /admin/config/entities/Asset/fields | J6: Field returned in list; column custom__asset_tag exists in assets table
A7: 2 | B7: P0-2-F-002 | C7: Field Management | D7: Integration | E7: P1-Critical | F7: Custom field persists data correctly | G7: ⬜ NOT RUN | H7: asset_tag field created | I7: 1. POST /assets {asset_tag:'EQ-001', ...other required fields} 2. GET /assets/:id | J7: asset_tag value 'EQ-001' returned in response
A8: 3 | B8: P0-2-F-003 | C8: Field Management | D8: API | E8: P2-High | F8: All field types can be created | G8: ⬜ NOT RUN | H8: Asset entity | I8: Create one field of each type: TEXT, NUMBER, DATE, DATETIME, BOOLEAN, PICKLIST, LOOKUP, ATTACHMENT | J8: All fields created; each stores and retrieves correct data type
A9: 4 | B9: P0-2-F-004 | C9: Field Management | D9: API | E9: P2-High | F9: Field deactivation hides field from UI (not deleted) | G9: ⬜ NOT RUN | H9: Custom field exists with data | I9: 1. PATCH field {is_active:false} 2. GET form layout | J9: Field absent from form; column still in DB; data preserved
A10: Server-Side Validation
A11: 1 | B11: P0-2-V-001 | C11: Server-Side Validation | D11: API | E11: P1-Critical | F11: Global required field blocks save at API level | G11: ⬜ NOT RUN | H11: asset_tag field has is_required_global=true | I11: 1. POST /assets without asset_tag field | J11: 422 returned with {field:'asset_tag', message:'Required'} — not just a UI warning
A12: 2 | B12: P0-2-V-002 | C12: Server-Side Validation | D12: API | E12: P1-Critical | F12: Conditional required — field required only when condition met | G12: ⬜ NOT RUN | H12: Field rule: asset_tag required when priority=CRITICAL | I12: 1. POST /assets {priority:'HIGH'} — no asset_tag 2. POST /assets {priority:'CRITICAL'} — no asset_tag | J12: Step 1 succeeds; step 2 returns 422
A13: 3 | B13: P0-2-V-003 | C13: Server-Side Validation | D13: API | E13: P2-High | F13: Regex validation on text field | G13: ⬜ NOT RUN | H13: Field has validation_rules: {regex:'^EQ-[0-9]{3}$'} | I13: 1. POST /assets {asset_tag:'WRONG'} 2. POST /assets {asset_tag:'EQ-001'} | J13: Step 1 returns 422 with regex error; step 2 succeeds
A14: 4 | B14: P0-2-V-004 | C14: Server-Side Validation | D14: Security | E14: P1-Critical | F14: Validation cannot be bypassed via API (front-end bypass attempt) | G14: ⬜ NOT RUN | H14: Required field configured | I14: 1. Make direct API call omitting required field (no front-end) | J14: Server returns 422; required field not optional at API level
A15: Form Designer
A16: 1 | B16: P0-2-D-001 | C16: Form Designer | D16: E2E | E16: P2-High | F16: Create 3-column form layout via designer | G16: ⬜ NOT RUN | H16: Admin logged in; Form Designer page open | I16: 1. Drag 3 fields into a row 2. Save layout 3. Open entity form as regular user | J16: Form renders 3 columns on desktop
A17: 2 | B17: P0-2-D-002 | C17: Form Designer | D17: E2E | E17: P2-High | F17: Form collapses to 1 column on phone viewport | G17: ⬜ NOT RUN | H17: 3-column layout saved | I17: 1. Open entity form 2. Resize browser to 375px width | J17: Form shows 1 column; all fields still accessible
A18: 3 | B18: P0-2-D-003 | C18: Form Designer | D18: E2E | E18: P3-Medium | F18: Role-specific form variant | G18: ⬜ NOT RUN | H18: Two roles: Technician, Manager | I18: 1. Create separate layouts for each role 2. Login as each role | J18: Each role sees their configured layout; Technician does not see Manager-only fields
A19: 4 | B19: P0-2-D-004 | C19: Form Designer | D19: E2E | E19: P3-Medium | F19: Preview mode in designer shows correct breakpoints | G19: ⬜ NOT RUN | H19: Admin in Form Designer | I19: 1. Click Desktop / Tablet / Phone preview toggles | J19: Preview iframe renders correct column count for each breakpoint
A20: Picklist Management
A21: 1 | B21: P0-2-P-001 | C21: Picklist Management | D21: API | E21: P2-High | F21: Create cascading picklist (parent-child) | G21: ⬜ NOT RUN | H21: Admin auth | I21: 1. Create picklist 'AssetClass' with values [Mechanical, Electrical] 2. Create picklist 'AssetSubClass' with parent_value links 3. Filter by parent value | J21: Only child values of selected parent returned
A22: 2 | B22: P0-2-P-002 | C22: Picklist Management | D22: API | E22: P2-High | F22: Per-org picklist override | G22: ⬜ NOT RUN | H22: Multi-org tenant | I22: 1. Global picklist has value 'Standard' 2. Create org-level override with extra value 'Custom' 3. Fetch picklist as Org A user | J22: Org A user sees both 'Standard' and 'Custom'; Org B user sees only 'Standard'
A23: 3 | B23: P0-2-P-003 | C23: Picklist Management | D23: API | E23: P3-Medium | F23: Effective-date picklist value | G23: ⬜ NOT RUN | H23: Picklist value with effective_to in the past | I23: 1. Fetch picklist values | J23: Expired value not returned in active list; historical records still display it
A24: Config Versioning & Export/Import
A25: 1 | B25: P0-2-CV-001 | C25: Config Versioning & Export/Import | D25: API | E25: P2-High | F25: Config version created on field change | G25: ⬜ NOT RUN | H25: Existing field definition | I25: 1. PUT /admin/config/entities/Asset/fields/:id {label:'New Label'} 2. GET /admin/config/versions?entity=field_definition&entityId=:id | J25: Version entry exists with old and new state snapshot
A26: 2 | B26: P0-2-CV-002 | C26: Config Versioning & Export/Import | D26: API | E26: P2-High | F26: Rollback config version | G26: ⬜ NOT RUN | H26: Version history with 2 versions | I26: 1. POST /admin/config/versions/:v1id/rollback 2. GET field definition | J26: Field definition matches v1 snapshot; custom DB column unchanged
A27: 3 | B27: P0-2-CV-003 | C27: Config Versioning & Export/Import | D27: API | E27: P2-High | F27: Export + import config JSON | G27: ⬜ NOT RUN | H27: Dev environment with custom fields | I27: 1. GET /admin/config/export?entities[]=Asset 2. POST /admin/config/import to clean Test env | J27: All field and form definitions present in Test; no errors
A28: 4 | B28: P0-2-CV-004 | C28: Config Versioning & Export/Import | D28: API | E28: P3-Medium | F28: Import conflict detection | G28: ⬜ NOT RUN | H28: Test env already has field 'asset_tag' | I28: 1. Import config that also defines 'asset_tag' with different type | J28: Conflict flagged in import response; no silent overwrite

Sheet 🔄 P0-3 Workflow
A2: EAM Phase 0 — P0-3 Schema Extension & Workflow Builder | Test Cases
A3: Workstream: P0-3 • Pass: =COUNTIF(G5:G5000,"✅ PASS") | Fail: =COUNTIF(G5:G5000,"❌ FAIL") | Total: =COUNTA(B5:B5000)
A4: # | B4: Test ID | C4: Category | D4: Type | E4: Priority | F4: Test Title | G4: Status | H4: Preconditions | I4: Test Steps | J4: Expected Result | K4: Actual Result | L4: Tester | M4: Date Tested | N4: Notes / Defect Ref
A5: Schema Extension (DDL)
A6: 1 | B6: P0-3-S-001 | C6: Schema Extension (DDL) | D6: Integration | E6: P1-Critical | F6: Add column via API — column exists in DB | G6: ⬜ NOT RUN | H6: Asset table exists; Postgres running | I6: 1. POST /admin/config/entities/Asset/fields (triggers DDL) 2. Query information_schema.columns for custom__new_field | J6: Column exists with correct type; migration logged as SUCCESS
A7: 2 | B7: P0-3-S-002 | C7: Schema Extension (DDL) | D7: Integration | E7: P1-Critical | F7: DDL is idempotent (IF NOT EXISTS) | G7: ⬜ NOT RUN | H7: Custom column already exists | I7: 1. Call addColumn for same field again | J7: No error; no duplicate column; migration log shows SKIPPED or SUCCESS
A8: 3 | B8: P0-3-S-003 | C8: Schema Extension (DDL) | D8: Integration | E8: P2-High | F8: Advisory lock prevents concurrent DDL on same table | G8: ⬜ NOT RUN | H8: Two concurrent addColumn requests for 'assets' table | I8: 1. Fire 2 simultaneous addColumn requests 2. Check schema_migrations | J8: Both succeed eventually; no corruption; lock contention handled gracefully
A9: 4 | B9: P0-3-S-004 | C9: Schema Extension (DDL) | D9: Integration | E9: P2-High | F9: Index created for searchable field | G9: ⬜ NOT RUN | H9: Field created with is_searchable=true | I9: 1. Query pg_indexes for custom__field_name on assets table | J9: Index exists; created with CONCURRENTLY (non-blocking)
A10: 5 | B10: P0-3-S-005 | C10: Schema Extension (DDL) | D10: Integration | E10: P2-High | F10: Soft-drop renames column with _deleted_ prefix | G10: ⬜ NOT RUN | H10: Custom column exists | I10: 1. DELETE /admin/config/entities/Asset/fields/:id 2. Check column name in DB | J10: Column renamed to custom___deleted__field_name; data preserved
A11: Workflow Engine — Node Types
A12: 1 | B12: P0-3-W-001 | C12: Workflow Engine — Node Types | D12: Unit | E12: P1-Critical | F12: DECISION node — correct branch on SQL condition | G12: ⬜ NOT RUN | H12: WorkflowEngine unit test | I12: 1. Create workflow: START → DECISION (totalcost>100000 → Finance path, else → Manager path) → END 2. Run with context {totalcost:150000} | J12: Finance path taken
A13: 2 | B13: P0-3-W-002 | C13: Workflow Engine — Node Types | D13: Unit | E13: P1-Critical | F13: DECISION node — alternate branch | G13: ⬜ NOT RUN | H13: Same workflow | I13: 1. Run with context {totalcost:80000} | J13: Manager path taken
A14: 3 | B14: P0-3-W-003 | C14: Workflow Engine — Node Types | D14: Integration | E14: P1-Critical | F14: TASK node creates workflow_task record | G14: ⬜ NOT RUN | H14: Workflow with TASK node assigned to role 'Supervisor' | I14: 1. Start workflow instance 2. Query workflow_tasks | J14: Task record in PENDING status; assigned_to_role='Supervisor'
A15: 4 | B15: P0-3-W-004 | C15: Workflow Engine — Node Types | D15: Integration | E15: P1-Critical | F15: APPROVAL node — approve action advances workflow | G15: ⬜ NOT RUN | H15: Task in PENDING state | I15: 1. Call advanceTask(taskId, userId, 'APPROVE', 'Looks good') 2. Check instance state | J15: Task status=COMPLETED; next node activated; history entry recorded
A16: 5 | B16: P0-3-W-005 | C16: Workflow Engine — Node Types | D16: Integration | E16: P1-Critical | F16: APPROVAL node — reject routes to reject path | G16: ⬜ NOT RUN | H16: Workflow with reject_path configured | I16: 1. Call advanceTask with action='REJECT' | J16: Workflow takes reject_path; reject notification fired
A17: 6 | B17: P0-3-W-006 | C17: Workflow Engine — Node Types | D17: Unit | E17: P2-High | F17: SUPERVISOR assignment resolves via manager_id chain | G17: ⬜ NOT RUN | H17: User with manager_id set | I17: 1. Create TASK node with assignment_type=SUPERVISOR 2. Start workflow as user X | J17: Task assigned to user X's manager (resolved via users.manager_id)
A18: 7 | B18: P0-3-W-007 | C18: Workflow Engine — Node Types | D18: Integration | E18: P2-High | F18: SLA escalation — task reassigned after due_at | G18: ⬜ NOT RUN | H18: TASK node with SLA 5 minutes; escalation_role='Senior Manager' | I18: 1. Start workflow; do NOT complete task 2. Advance time past due_at 3. Run BullMQ job manually | J18: Task status=ESCALATED; new task created for Senior Manager; history records escalation
A19: 8 | B19: P0-3-W-008 | C19: Workflow Engine — Node Types | D19: Integration | E19: P2-High | F19: Workflow versioning — in-flight uses old version | G19: ⬜ NOT RUN | H19: v1 published; v2 published afterwards | I19: 1. Start workflow (uses v1) 2. Publish v2 3. Advance task on v1 instance | J19: v1 instance completes using v1 definition; new instance after step 2 uses v2
A20: 9 | B20: P0-3-W-009 | C20: Workflow Engine — Node Types | D20: Integration | E20: P2-High | F20: PARALLEL_SPLIT — multiple tasks created simultaneously | G20: ⬜ NOT RUN | H20: Workflow with parallel split to 2 paths | I20: 1. Start workflow 2. Query workflow_tasks | J20: 2 tasks created simultaneously; both in PENDING
A21: 10 | B21: P0-3-W-010 | C21: Workflow Engine — Node Types | D21: Integration | E21: P2-High | F21: SYNCHRONISE — waits for all parallel tasks | G21: ⬜ NOT RUN | H21: Workflow: split → 2 tasks → sync → end | I21: 1. Complete task 1 only 2. Check instance state | J21: Instance still RUNNING; END not reached until task 2 also completed
A22: Workflow Designer UI
A23: 1 | B23: P0-3-D-001 | C23: Workflow Designer UI | D23: E2E | E23: P2-High | F23: Create and publish workflow via designer | G23: ⬜ NOT RUN | H23: Admin in Workflow Designer | I23: 1. Drag START → DECISION → TASK → END nodes 2. Configure condition on DECISION 3. Click Publish | J23: Workflow saved to workflow_definitions with version=1 and is_active=true
A24: 2 | B24: P0-3-D-002 | C24: Workflow Designer UI | D24: E2E | E24: P2-High | F24: Simulate mode — correct branch highlighted | G24: ⬜ NOT RUN | H24: Published workflow with DECISION node | I24: 1. Click Simulate 2. Enter test values {totalcost:200000} 3. Click Next | J24: Correct branch highlighted in canvas; no workflow_instances created in DB
A25: 3 | B25: P0-3-D-003 | C25: Workflow Designer UI | D25: E2E | E25: P3-Medium | F25: Workflow binding to entity trigger | G25: ⬜ NOT RUN | H25: Published workflow | I25: 1. Set workflow to trigger on SR_CREATED for ServiceRequest entity 2. Create SR | J25: Workflow instance auto-starts on SR creation

Sheet 🔌 P0-4 Integration
A2: EAM Phase 0 — P0-4 Integration Framework | Test Cases
A3: Workstream: P0-4 • Pass: =COUNTIF(G5:G5000,"✅ PASS") | Fail: =COUNTIF(G5:G5000,"❌ FAIL") | Total: =COUNTA(B5:B5000)
A4: # | B4: Test ID | C4: Category | D4: Type | E4: Priority | F4: Test Title | G4: Status | H4: Preconditions | I4: Test Steps | J4: Expected Result | K4: Actual Result | L4: Tester | M4: Date Tested | N4: Notes / Defect Ref
A5: REST Adapter
A6: 1 | B6: P0-4-R-001 | C6: REST Adapter | D6: Integration | E6: P2-High | F6: REST adapter executes GET request and maps response | G6: ⬜ NOT RUN | H6: Mock HTTP server (msw) running | I6: 1. Configure REST connection to mock server 2. Create job to GET /test-endpoint 3. Run job | J6: Response received; fields mapped to EAM record per mapping_config; run_log=SUCCESS
A7: 2 | B7: P0-4-R-002 | C7: REST Adapter | D7: Integration | E7: P2-High | F7: REST adapter with OAuth2 client credentials | G7: ⬜ NOT RUN | H7: Mock OAuth2 token endpoint | I7: 1. Configure connection with auth_type=OAUTH2_CLIENT_CREDENTIALS 2. Run job | J7: Token fetched; Bearer header set on subsequent calls; token cached until expiry
A8: 3 | B8: P0-4-R-003 | C8: REST Adapter | D8: Integration | E8: P2-High | F8: REST adapter retry on 5xx error | G8: ⬜ NOT RUN | H8: Mock server returns 503 twice then 200 | I8: 1. Configure retry_attempts=3 2. Run job | J8: Job succeeds on 3rd attempt; retry attempts logged
A9: 4 | B9: P0-4-R-004 | C9: REST Adapter | D9: Integration | E9: P3-Medium | F9: REST adapter test connection | G9: ⬜ NOT RUN | H9: Admin auth | I9: 1. POST /admin/integrations/connections/:id/test | J9: Returns {success:true, latency_ms} if reachable; {success:false, error} if not
A10: SFTP Adapter
A11: 1 | B11: P0-4-S-001 | C11: SFTP Adapter | D11: Integration | E11: P2-High | F11: SFTP inbound — pick up CSV and create records | G11: ⬜ NOT RUN | H11: Mock SFTP server with test CSV file | I11: 1. Configure SFTP inbound job 2. Run job 3. Check EAM entity records | J11: CSV rows mapped to EAM records; file archived/removed per config; run_log shows record count
A12: 2 | B12: P0-4-S-002 | C12: SFTP Adapter | D12: Integration | E12: P3-Medium | F12: SFTP outbound — generate CSV from query | G12: ⬜ NOT RUN | H12: EAM has work order records | I12: 1. Configure outbound job with query selecting open WOs 2. Run job | J12: CSV file uploaded to SFTP path; filename has timestamp
A13: Webhook Outbound
A14: 1 | B14: P0-4-W-001 | C14: Webhook Outbound | D14: Integration | E14: P1-Critical | F14: Webhook fires on entity status change | G14: ⬜ NOT RUN | H14: Webhook subscription active; listener server running | I14: 1. Change WO status 2. Check webhook listener | J14: JSON payload delivered within 5s; X-EAM-Signature header present and verifiable
A15: 2 | B15: P0-4-W-002 | C15: Webhook Outbound | D15: Integration | E15: P1-Critical | F15: HMAC signature verification | G15: ⬜ NOT RUN | H15: Webhook payload received | I15: 1. Compute HMAC-SHA256 of payload body using shared secret 2. Compare to header value | J15: Signatures match; payload not tampered
A16: 3 | B16: P0-4-W-003 | C16: Webhook Outbound | D16: Integration | E16: P2-High | F16: Webhook retry on delivery failure | G16: ⬜ NOT RUN | H16: Listener returns 500 | I16: 1. Fire webhook 2. Listener returns 503 three times | J16: 3 retries with exponential backoff (1s, 2s, 4s); dead-lettered after 3rd failure; admin alerted
A17: 4 | B17: P0-4-W-004 | C17: Webhook Outbound | D17: Integration | E17: P2-High | F17: Admin disables webhook subscription | G17: ⬜ NOT RUN | H17: Active subscription | I17: 1. Set subscription is_active=false 2. Trigger entity change | J17: No webhook delivery; no delivery log entry for that subscription
A18: Integration Admin UI
A19: 1 | B19: P0-4-A-001 | C19: Integration Admin UI | D19: E2E | E19: P3-Medium | F19: Create connection, test, save | G19: ⬜ NOT RUN | H19: Admin in Integration admin UI | I19: 1. Create REST connection with valid URL 2. Click Test 3. Save | J19: Test result shown; connection saved; appears in connections list
A20: 2 | B20: P0-4-A-002 | C20: Integration Admin UI | D20: E2E | E20: P3-Medium | F20: View run history and error log | G20: ⬜ NOT RUN | H20: Job has been run with one failure | I20: 1. Navigate to job run history | J20: Both successful and failed runs shown; error details expandable
A21: 3 | B21: P0-4-A-003 | C21: Integration Admin UI | D21: E2E | E21: P3-Medium | F21: Manual trigger of scheduled job | G21: ⬜ NOT RUN | H21: Admin on job detail page | I21: 1. Click 'Run Now' | J21: Job queued immediately; run log entry created; status updates in UI

Sheet 📎 P0-5 Attachments
A2: EAM Phase 0 — P0-5 Attachment Service & Virus Scanning | Test Cases
A3: Workstream: P0-5 • Pass: =COUNTIF(G5:G5000,"✅ PASS") | Fail: =COUNTIF(G5:G5000,"❌ FAIL") | Total: =COUNTA(B5:B5000)
A4: # | B4: Test ID | C4: Category | D4: Type | E4: Priority | F4: Test Title | G4: Status | H4: Preconditions | I4: Test Steps | J4: Expected Result | K4: Actual Result | L4: Tester | M4: Date Tested | N4: Notes / Defect Ref
A5: Upload Pipeline
A6: 1 | B6: P0-5-U-001 | C6: Upload Pipeline | D6: Integration | E6: P1-Critical | F6: Standard upload flow — presign → upload → confirm | G6: ⬜ NOT RUN | H6: MinIO running; document type 'General' configured | I6: 1. POST /attachments/presign {documentType:'General', filename:'test.pdf'} 2. PUT file to presigned URL 3. POST /attachments/:id/confirm | J6: Attachment record created; scan_status=PENDING then CLEAN; download URL works
A7: 2 | B7: P0-5-U-002 | C7: Upload Pipeline | D7: API | E7: P1-Critical | F7: File extension rejected if not in allowed list | G7: ⬜ NOT RUN | H7: Document type allows only [pdf, jpg] | I7: 1. POST /attachments/presign {filename:'report.xlsx'} | J7: 422 returned; no presigned URL issued; no S3 object created
A8: 3 | B8: P0-5-U-003 | C8: Upload Pipeline | D8: API | E8: P2-High | F8: File size limit enforced at presign | G8: ⬜ NOT RUN | H8: Document type max_size=5MB | I8: 1. POST /attachments/presign {fileSize:10000000} | J8: 422 returned with size_limit_exceeded error
A9: 4 | B9: P0-5-U-004 | C9: Upload Pipeline | D9: Integration | E9: P2-High | F9: SHA-256 checksum recorded | G9: ⬜ NOT RUN | H9: After successful upload | I9: 1. GET /attachments/:id/metadata | J9: checksum_sha256 field populated with correct hash of uploaded file
A10: Virus Scanning
A11: 1 | B11: P0-5-V-001 | C11: Virus Scanning | D11: Integration | E11: P1-Critical | F11: EICAR test file triggers QUARANTINE action | G11: ⬜ NOT RUN | H11: ClamAV running; document type virus_scan_action=QUARANTINE | I11: 1. Upload EICAR test string as .txt file 2. Wait for scan worker 3. GET /attachments/:id/metadata | J11: scan_status=INFECTED; file moved to quarantine prefix in S3; download returns 403
A12: 2 | B12: P0-5-V-002 | C12: Virus Scanning | D12: Integration | E12: P1-Critical | F12: EICAR file triggers REJECT action | G12: ⬜ NOT RUN | H12: Document type virus_scan_action=REJECT | I12: 1. Upload EICAR test string | J12: File deleted from S3; attachment.deleted_at set; uploader notification sent
A13: 3 | B13: P0-5-V-003 | C13: Virus Scanning | D13: Integration | E13: P2-High | F13: EICAR file triggers ALERT action — file still accessible | G13: ⬜ NOT RUN | H13: Document type virus_scan_action=ALERT | I13: 1. Upload EICAR test string 2. GET /attachments/:id/download | J13: scan_status=INFECTED but download still returns URL; admin notification sent
A14: 4 | B14: P0-5-V-004 | C14: Virus Scanning | D14: Integration | E14: P2-High | F14: virus_scan_enabled=false skips scan queue | G14: ⬜ NOT RUN | H14: Document type virus_scan_enabled=false | I14: 1. Upload any file 2. GET /attachments/:id/metadata immediately | J14: scan_status=null or N/A; file immediately downloadable; no BullMQ job queued
A15: 5 | B15: P0-5-V-005 | C15: Virus Scanning | D15: Integration | E15: P2-High | F15: ClamAV unavailable with BLOCK fallback | G15: ⬜ NOT RUN | H15: ClamAV service stopped; fallback_action=BLOCK | I15: 1. POST /attachments/presign + confirm | J15: Upload blocked with service_unavailable error; file not stored
A16: Attachment Library & Versioning
A17: 1 | B17: P0-5-L-001 | C17: Attachment Library & Versioning | D17: Integration | E17: P2-High | F17: Same file linked to two entity records — single S3 object | G17: ⬜ NOT RUN | H17: Existing attachment | I17: 1. POST /attachments/:id/link {entityType:'WorkOrder',entityId:'WO-002'} 2. Check S3 object count | J17: One S3 object; two attachment_links records; storage_key identical
A18: 2 | B18: P0-5-L-002 | C18: Attachment Library & Versioning | D18: Integration | E18: P2-High | F18: Deleting one link does not delete S3 object | G18: ⬜ NOT RUN | H18: Attachment linked to WO-001 and WO-002 | I18: 1. DELETE /attachments/:id?entityType=WorkOrder&entityId=WO-001 2. GET /attachments for WO-002 | J18: WO-001 link removed; WO-002 attachment still present and downloadable
A19: 3 | B19: P0-5-L-003 | C19: Attachment Library & Versioning | D19: Integration | E19: P2-High | F19: Upload new version of existing attachment | G19: ⬜ NOT RUN | H19: Attachment v1 exists | I19: 1. Upload new file with version_of=:existingId 2. GET /attachments/:id/versions | J19: Two version records; download default returns v2; v1 still accessible
A20: 4 | B20: P0-5-L-004 | C20: Attachment Library & Versioning | D20: API | E20: P3-Medium | F20: Retention policy flag — attachment marked for review | G20: ⬜ NOT RUN | H20: Document type retention_days=30; attachment uploaded 31 days ago (set created_at in DB) | I20: 1. Run retention check job | J20: Attachment flagged with expires_at in the past; appears in admin retention review list

Sheet 📊 P0-6 Reporting
A2: EAM Phase 0 — P0-6 Reporting Engine & BI Adapters | Test Cases
A3: Workstream: P0-6 • Pass: =COUNTIF(G5:G5000,"✅ PASS") | Fail: =COUNTIF(G5:G5000,"❌ FAIL") | Total: =COUNTA(B5:B5000)
A4: # | B4: Test ID | C4: Category | D4: Type | E4: Priority | F4: Test Title | G4: Status | H4: Preconditions | I4: Test Steps | J4: Expected Result | K4: Actual Result | L4: Tester | M4: Date Tested | N4: Notes / Defect Ref
A5: Query Builder & Security
A6: 1 | B6: P0-6-Q-001 | C6: Query Builder & Security | D6: Unit | E6: P1-Critical | F6: tenant_id always injected into queries | G6: ⬜ NOT RUN | H6: ReportQueryBuilder unit test | I6: 1. Build query for 'work_orders' subject 2. Inspect generated SQL | J6: WHERE clause always includes tenant_id = $1 parameter; never string-concatenated
A7: 2 | B7: P0-6-Q-002 | C7: Query Builder & Security | D7: Security | E7: P1-Critical | F7: SQL injection attempt via filter field | G7: ⬜ NOT RUN | H7: Report with user-controlled filter value | I7: 1. Pass filter value: '; DROP TABLE work_orders; --' | J7: QueryBuilder rejects or escapes; no DDL executed; 400 returned
A8: 3 | B8: P0-6-Q-003 | C8: Query Builder & Security | D8: Security | E8: P1-Critical | F8: Tenant A cannot access Tenant B data | G8: ⬜ NOT RUN | H8: Two tenants with work orders | I8: 1. Run report as Tenant A user 2. Check results | J8: Only Tenant A work orders in results; Tenant B rows absent
A9: 4 | B9: P0-6-Q-004 | C9: Query Builder & Security | D9: Unit | E9: P2-High | F9: All filter operators work correctly | G9: ⬜ NOT RUN | H9: QueryBuilder unit tests | I9: Test EQUALS, NOT_EQUALS, CONTAINS, STARTS_WITH, IN, BETWEEN, IS_NULL operators | J9: Each generates correct parameterised SQL clause
A10: Report Designer & Export
A11: 1 | B11: P0-6-D-001 | C11: Report Designer & Export | D11: E2E | E11: P2-High | F11: Non-developer creates report without SQL | G11: ⬜ NOT RUN | H11: Admin in Report Designer | I11: 1. Select 'work_orders' subject 2. Drag 3 fields 3. Add filter (status=OPEN) 4. Preview | J11: Preview shows rows matching filter; no SQL entered by user
A12: 2 | B12: P0-6-D-002 | C12: Report Designer & Export | D12: E2E | E12: P2-High | F12: Export report as PDF | G12: ⬜ NOT RUN | H12: Report defined | I12: 1. POST /reports/definitions/:id/run {format:'PDF'} 2. Download file | J12: PDF downloaded; has header with report name + date; rows formatted as table
A13: 3 | B13: P0-6-D-003 | C13: Report Designer & Export | D13: E2E | E13: P2-High | F13: Export report as XLSX | G13: ⬜ NOT RUN | H13: Report defined | I13: 1. POST /reports/definitions/:id/run {format:'XLSX'} | J13: XLSX file; header row styled; auto-filter enabled; no formula errors
A14: 4 | B14: P0-6-D-004 | C14: Report Designer & Export | D14: E2E | E14: P3-Medium | F14: Schedule report — weekly delivery | G14: ⬜ NOT RUN | H14: Report defined; SMTP configured | I14: 1. Create schedule: weekly Monday 08:00; recipient role 'Admin'; format PDF 2. Trigger manually | J14: Email delivered to all Admin users with PDF attachment; run_log records row_count
A15: 5 | B15: P0-6-D-005 | C15: Report Designer & Export | D15: Integration | E15: P2-High | F15: Skip-if-empty schedule — no email when 0 rows | G15: ⬜ NOT RUN | H15: Schedule with skip_if_empty=true; empty result set | I15: 1. Trigger scheduled run | J15: No email sent; run_log status=SKIPPED; row_count=0
A16: BI Adapters
A17: 1 | B17: P0-6-B-001 | C17: BI Adapters | D17: Integration | E17: P2-High | F17: Power BI Direct Query — eam_reporting role | G17: ⬜ NOT RUN | H17: PostgreSQL read replica; eam_reporting role created | I17: 1. Connect via psql as eam_reporting 2. SELECT * FROM rpt_tenant_X_work_orders 3. Try UPDATE | J17: SELECT succeeds with tenant-scoped data; UPDATE returns permission denied
A18: 2 | B18: P0-6-B-002 | C18: BI Adapters | D18: Integration | E18: P2-High | F18: Tableau WDC schema endpoint | G18: ⬜ NOT RUN | H18: WDC endpoint deployed | I18: 1. GET /reporting/tableau-wdc/work_orders/schema | J18: Returns JSON with columns array; field types are correct Tableau types
A19: 3 | B19: P0-6-B-003 | C19: BI Adapters | D19: Integration | E19: P2-High | F19: Tableau WDC data endpoint — pagination | G19: ⬜ NOT RUN | H19: work_orders subject has > 100 rows | I19: 1. GET /reporting/tableau-wdc/work_orders/data?page=1&limit=100 | J19: Returns 100 rows; has_more=true; page=2 returns next batch
A20: 4 | B20: P0-6-B-004 | C20: BI Adapters | D20: Integration | E20: P3-Medium | F20: Qlik export generates CSV to S3 | G20: ⬜ NOT RUN | H20: Qlik adapter configured | I20: 1. POST /admin/reporting/bi/qlik/export/work_orders | J20: CSV file in S3 at configured prefix; file contains correct tenant data
A21: 5 | B21: P0-6-B-005 | C21: BI Adapters | D21: Integration | E21: P3-Medium | F21: BIRT rptdesign upload and render | G21: ⬜ NOT RUN | H21: BIRT runtime container running | I21: 1. Upload sample.rptdesign 2. GET /admin/reporting/birt/:id/run?format=PDF | J21: PDF rendered by BIRT runtime; proxied back to caller

Sheet 🖥️ P0-7 Dashboard
A2: EAM Phase 0 — P0-7 User Dashboard & Active-User Collaboration | Test Cases
A3: Workstream: P0-7 • Pass: =COUNTIF(G5:G5000,"✅ PASS") | Fail: =COUNTIF(G5:G5000,"❌ FAIL") | Total: =COUNTA(B5:B5000)
A4: # | B4: Test ID | C4: Category | D4: Type | E4: Priority | F4: Test Title | G4: Status | H4: Preconditions | I4: Test Steps | J4: Expected Result | K4: Actual Result | L4: Tester | M4: Date Tested | N4: Notes / Defect Ref
A5: Dashboard Configuration
A6: 1 | B6: P0-7-D-001 | C6: Dashboard Configuration | D6: E2E | E6: P2-High | F6: Role-default dashboard shown to new user | G6: ⬜ NOT RUN | H6: Admin has set default layout for 'Technician' role with 2 widgets | I6: 1. Create new user with Technician role 2. Login | J6: Dashboard shows 2 pre-configured widgets; no manual setup required
A7: 2 | B7: P0-7-D-002 | C7: Dashboard Configuration | D7: E2E | E7: P2-High | F7: User personalises layout — persists across sessions | G7: ⬜ NOT RUN | H7: User logged in | I7: 1. Drag widget to new position 2. Logout 3. Login again | J7: Widget in new position; layout saved to user_dashboards
A8: 3 | B8: P0-7-D-003 | C8: Dashboard Configuration | D8: E2E | E8: P2-High | F8: User resets to role default | G8: ⬜ NOT RUN | H8: User has personalised layout | I8: 1. Click 'Reset to Default' 2. Confirm | J8: Layout reverts to role default; user_dashboards row updated
A9: 4 | B9: P0-7-D-004 | C9: Dashboard Configuration | D9: E2E | E9: P3-Medium | F9: Multiple named dashboard tabs | G9: ⬜ NOT RUN | H9: User logged in | I9: 1. Add new tab named 'Procurement' 2. Add widgets to it 3. Switch tabs | J9: Both tabs persist; each has independent widget layout
A10: Widget Functionality
A11: 1 | B11: P0-7-W-001 | C11: Widget Functionality | D11: Integration | E11: P2-High | F11: KPI tile shows correct aggregate value | G11: ⬜ NOT RUN | H11: Work orders in DB; KPI tile configured for count of OPEN WOs | I11: 1. Open dashboard with KPI tile | J11: Tile shows correct count matching DB query; refreshes per configured interval
A12: 2 | B12: P0-7-W-002 | C12: Widget Functionality | D12: Integration | E12: P2-High | F12: List widget shows top-N records | G12: ⬜ NOT RUN | H12: List widget: entity=WorkOrder, filter={status:OPEN}, max_rows=5 | I12: 1. Open dashboard | J12: Up to 5 open WOs shown; click on row navigates to WO detail
A13: 3 | B13: P0-7-W-003 | C13: Widget Functionality | D13: Performance | E13: P2-High | F13: Slow widget does not block other widgets | G13: ⬜ NOT RUN | H13: One widget configured with a slow query (forced via mock) | I13: 1. Open dashboard 2. Observe load order | J13: Fast widgets show data while slow widget shows skeleton; page not blocked
A14: 4 | B14: P0-7-W-004 | C14: Widget Functionality | D14: Integration | E14: P3-Medium | F14: Chart widget auto-refreshes | G14: ⬜ NOT RUN | H14: Chart widget with refresh_interval=60s | I14: 1. Open dashboard 2. Wait 60+ seconds 3. Observe network requests | J14: New data request fired after 60s; chart updates without page reload
A15: 5 | B15: P0-7-W-005 | C15: Widget Functionality | D15: Integration | E15: P2-High | F15: Active Users widget shows online users | G15: ⬜ NOT RUN | H15: Two users logged in (Playwright 2-tab test) | I15: 1. Both users open dashboard 2. Check Active Users widget | J15: Both users appear as ONLINE; status updates within heartbeat interval
A16: Presence & Chat
A17: 1 | B17: P0-7-C-001 | C17: Presence & Chat | D17: E2E | E17: P1-Critical | F17: Direct message delivered in real time | G17: ⬜ NOT RUN | H17: Two browser sessions (User A and User B) | I17: 1. User A sends message to User B 2. Observe User B's chat window | J17: Message appears in User B's chat within 2 seconds
A18: 2 | B18: P0-7-C-002 | C18: Presence & Chat | D18: E2E | E18: P2-High | F18: Unread badge increments on new message | G18: ⬜ NOT RUN | H18: User B has chat closed | I18: 1. User A sends message to User B | J18: User B's bell/chat icon shows unread badge count = 1
A19: 3 | B19: P0-7-C-003 | C19: Presence & Chat | D19: E2E | E19: P2-High | F19: Context link in chat from WO detail page | G19: ⬜ NOT RUN | H19: WO-001 detail page | I19: 1. User A clicks Share from WO-001 2. Selects User B 3. Sends | J19: User B receives message with WO-001 link; clicking link navigates to WO-001
A20: 4 | B20: P0-7-C-004 | C20: Presence & Chat | D20: Integration | E20: P2-High | F20: User goes offline after disconnect | G20: ⬜ NOT RUN | H20: User A connected | I20: 1. User A closes browser tab 2. Wait > 5s grace period 3. Check presence | J20: User A presence status=OFFLINE; Active Users widget updates
A21: 5 | B21: P0-7-C-005 | C21: Presence & Chat | D21: Integration | E21: P3-Medium | F21: DND status visible to others | G21: ⬜ NOT RUN | H21: User A sets DND | I21: 1. User A emits status:update {status:DND} 2. User B checks Active Users | J21: User A shown with amber indicator

Sheet 📧 P0-8 Notifications
A2: EAM Phase 0 — P0-8 Email Notification Framework | Test Cases
A3: Workstream: P0-8 • Pass: =COUNTIF(G5:G5000,"✅ PASS") | Fail: =COUNTIF(G5:G5000,"❌ FAIL") | Total: =COUNTA(B5:B5000)
A4: # | B4: Test ID | C4: Category | D4: Type | E4: Priority | F4: Test Title | G4: Status | H4: Preconditions | I4: Test Steps | J4: Expected Result | K4: Actual Result | L4: Tester | M4: Date Tested | N4: Notes / Defect Ref
A5: Email Delivery
A6: 1 | B6: P0-8-E-001 | C6: Email Delivery | D6: Integration | E6: P1-Critical | F6: Email sent on WO_ASSIGNED event | G6: ⬜ NOT RUN | H6: Notification trigger active for WO_ASSIGNED; Mailhog SMTP configured | I6: 1. Create WO with assigned_to_user_id set 2. Check Mailhog inbox | J6: Email arrives within 30s; subject and body contain correct WO number and assignee name
A7: 2 | B7: P0-8-E-002 | C7: Email Delivery | D7: Integration | E7: P1-Critical | F7: Merge fields render correctly in template | G7: ⬜ NOT RUN | H7: Template with {{workorder.num}}, {{asset.description}}, {{assignee.name}} | I7: 1. Trigger email event 2. Inspect email body | J7: All merge fields replaced with actual values; no {{placeholder}} strings visible
A8: 3 | B8: P0-8-E-003 | C8: Email Delivery | D8: Integration | E8: P2-High | F8: Plain-text fallback sent alongside HTML | G8: ⬜ NOT RUN | H8: Email client set to plain text only | I8: 1. Inspect raw email MIME | J8: Email has both text/html and text/plain parts
A9: 4 | B9: P0-8-E-004 | C9: Email Delivery | D9: Integration | E9: P2-High | F9: Hard SMTP bounce marks user email_bounced | G9: ⬜ NOT RUN | H9: SMTP mock returns 550 permanent failure | I9: 1. Send notification to bouncing address | J9: delivery_log status=FAILED; user.email_bounced=true; admin alerted
A10: 5 | B10: P0-8-E-005 | C10: Email Delivery | D10: Integration | E10: P2-High | F10: Delivery log records every send | G10: ⬜ NOT RUN | H10: Multiple notifications triggered | I10: 1. GET /admin/notifications/delivery-log | J10: All send attempts logged with status, timestamp, recipient, event type
A11: Triggers & Conditions
A12: 1 | B12: P0-8-T-001 | C12: Triggers & Conditions | D12: Integration | E12: P1-Critical | F12: Conditional trigger — only fires when condition met | G12: ⬜ NOT RUN | H12: Trigger for PR_APPROVED with condition totalcost>100000 | I12: 1. Approve PR with totalcost=80000 → check for email 2. Approve PR with totalcost=150000 → check | J12: Step 1: no email. Step 2: email sent
A13: 2 | B13: P0-8-T-002 | C13: Triggers & Conditions | D13: Integration | E13: P2-High | F13: Rate limiting — bulk update produces digest not N emails | G13: ⬜ NOT RUN | H13: Trigger with rate_limit: max=10 per 60s; 50 WOs updated | I13: 1. Update 50 WOs to APPR status 2. Check emails | J13: ≤ 10 emails (or 1 digest) sent; not 50
A14: 3 | B14: P0-8-T-003 | C14: Triggers & Conditions | D14: Integration | E14: P2-High | F14: Digest mode — batched email sent after window | G14: ⬜ NOT RUN | H14: Trigger with digest_config enabled; window=5min | I14: 1. Fire same event 5 times within window 2. Wait for window to close | J14: 1 digest email sent listing all 5 events; not 5 separate emails
A15: 4 | B15: P0-8-T-004 | C15: Triggers & Conditions | D15: Integration | E15: P3-Medium | F15: Admin disables trigger — no notifications fired | G15: ⬜ NOT RUN | H15: Active trigger | I15: 1. Set trigger is_active=false 2. Fire triggering event | J15: No email; no in-app notification; no delivery log entry
A16: In-App Notifications
A17: 1 | B17: P0-8-I-001 | C17: In-App Notifications | D17: E2E | E17: P1-Critical | F17: In-app notification delivered in real time | G17: ⬜ NOT RUN | H17: User logged in; WS connection active | I17: 1. Trigger event (WO assigned to user) 2. Observe notification bell | J17: Bell badge increments within 2s; notification visible in drawer
A18: 2 | B18: P0-8-I-002 | C18: In-App Notifications | D18: E2E | E18: P2-High | F18: User unsubscribes from email — still gets in-app | G18: ⬜ NOT RUN | H18: User has disabled email for WO_ASSIGNED | I18: 1. Assign WO to user | J18: No email; in-app notification still delivered
A19: 3 | B19: P0-8-I-003 | C19: In-App Notifications | D19: Integration | E19: P2-High | F19: Mark notification read | G19: ⬜ NOT RUN | H19: User has unread notification | I19: 1. POST /notifications/:id/read 2. GET /notifications | J19: is_read=true; read_at set; unread count decrements
A20: 4 | B20: P0-8-I-004 | C20: In-App Notifications | D20: Integration | E20: P3-Medium | F20: Mandatory trigger cannot be disabled by user | G20: ⬜ NOT RUN | H20: System trigger is_mandatory=true | I20: 1. User tries to disable via PUT /users/me/notification-preferences | J20: Preference update rejected for mandatory trigger; toggle locked in UI
A21: Admin Configuration
A22: 1 | B22: P0-8-A-001 | C22: Admin Configuration | D22: E2E | E22: P2-High | F22: SMTP configuration + test send | G22: ⬜ NOT RUN | H22: Admin on SMTP config page; Mailhog available | I22: 1. Enter SMTP credentials 2. Click Send Test Email | J22: Test email arrives in Mailhog; success message shown in UI
A23: 2 | B23: P0-8-A-002 | C23: Admin Configuration | D23: E2E | E23: P2-High | F23: Create new notification trigger with custom template | G23: ⬜ NOT RUN | H23: Admin on Triggers page | I23: 1. Create trigger for custom event type 2. Select custom template 3. Activate | J23: Trigger active; fires correctly on next matching event; no code change required
A24: 3 | B24: P0-8-A-003 | C24: Admin Configuration | D24: E2E | E24: P3-Medium | F24: Template preview renders correctly | G24: ⬜ NOT RUN | H24: Admin in Template editor | I24: 1. Edit template 2. Click Preview 3. Click Send Preview Email | J24: Preview renders with sample data; email arrives at admin's inbox

Sheet 🧩 Integration Sprint
A2: EAM Phase 0 — Integration Sprint — End-to-End & Non-Functional | Test Cases
A3: Workstream: INT • Pass: =COUNTIF(G5:G5000,"✅ PASS") | Fail: =COUNTIF(G5:G5000,"❌ FAIL") | Total: =COUNTA(B5:B5000)
A4: # | B4: Test ID | C4: Category | D4: Type | E4: Priority | F4: Test Title | G4: Status | H4: Preconditions | I4: Test Steps | J4: Expected Result | K4: Actual Result | L4: Tester | M4: Date Tested | N4: Notes / Defect Ref
A5: End-to-End Scenario
A6: 1 | B6: INT-E2E-001 | C6: End-to-End Scenario | D6: E2E | E6: P1-Critical | F6: Full Phase 0 integration scenario — Step 1: LDAP sync | G6: ⬜ NOT RUN | H6: All 8 services running; mock LDAP server; Playwright test | I6: 1. Admin logs in 2. Configures LDAP provider 3. Triggers sync | J6: New user testtech@eam.local appears in Users list with auth_source=LDAP
A7: 2 | B7: INT-E2E-002 | C7: End-to-End Scenario | D7: E2E | E7: P1-Critical | F7: Integration scenario — Step 2: Custom field added | G7: ⬜ NOT RUN | H7: Previous step passed | I7: 1. Admin adds text field 'Equipment Code' to Asset entity, marks required | J7: Field on Asset form; saving without it fails at API level
A8: 3 | B8: INT-E2E-003 | C8: End-to-End Scenario | D8: E2E | E8: P1-Critical | F8: Integration scenario — Step 3: Workflow created | G8: ⬜ NOT RUN | H8: Previous step passed | I8: 1. Admin creates SR workflow: START → TASK (Supervisor) → END 2. Binds to SR_CREATED | J8: Workflow published; binding active
A9: 4 | B9: INT-E2E-004 | C9: End-to-End Scenario | D9: E2E | E9: P1-Critical | F9: Integration scenario — Step 4: SR created starts workflow | G9: ⬜ NOT RUN | H9: Previous step passed | I9: 1. testtech@eam.local creates Service Request | J9: Workflow instance starts; task created for Supervisor role
A10: 5 | B10: INT-E2E-005 | C10: End-to-End Scenario | D10: E2E | E10: P1-Critical | F10: Integration scenario — Step 5: In-app notification received | G10: ⬜ NOT RUN | H10: Previous step passed | I10: 1. Check Supervisor user's notifications | J10: In-app notification 'New SR task assigned' appears in bell within 5s
A11: 6 | B11: INT-E2E-006 | C11: End-to-End Scenario | D11: E2E | E11: P1-Critical | F11: Integration scenario — Step 6: Attachment uploaded + scanned | G11: ⬜ NOT RUN | H11: Previous step passed | I11: 1. testtech uploads PDF to SR 2. Wait for scan worker | J11: Attachment scan_status=CLEAN; download URL works
A12: 7 | B12: INT-E2E-007 | C12: End-to-End Scenario | D12: E2E | E12: P1-Critical | F12: Integration scenario — Step 7: Workflow task approved | G12: ⬜ NOT RUN | H12: Previous step passed | I12: 1. Supervisor approves task via SR workflow panel | J12: Instance status=COMPLETED; history shows APPROVED; SR status updated
A13: 8 | B13: INT-E2E-008 | C13: End-to-End Scenario | D13: E2E | E13: P1-Critical | F13: Integration scenario — Step 8: SR appears in report | G13: ⬜ NOT RUN | H13: Previous step passed | I13: 1. Admin runs Service Requests report 2. Exports PDF | J13: New SR in results; PDF export successful
A14: 9 | B14: INT-E2E-009 | C14: End-to-End Scenario | D14: E2E | E14: P1-Critical | F14: Integration scenario — Step 9: Dashboard KPI updates | G14: ⬜ NOT RUN | H14: testtech dashboard has KPI tile 'My Open SRs' | I14: 1. Check KPI tile value | J14: Count reflects newly created SR
A15: 10 | B15: INT-E2E-010 | C15: End-to-End Scenario | D15: E2E | E15: P1-Critical | F15: Integration scenario — Step 10: Chat with record link | G15: ⬜ NOT RUN | H15: Previous step passed | I15: 1. testtech sends chat message to Supervisor with SR link | J15: Message delivered <2s; SR link renders in message; both parties see it
A16: Performance / Load
A17: 1 | B17: INT-P-001 | C17: Performance / Load | D17: Performance | E17: P1-Critical | F17: k6 load test — p50 < 800ms | G17: ⬜ NOT RUN | H17: k6 installed; staging environment running; 100 VUs | I17: Run k6 load-tests/phase0-baseline.js | J17: http_req_duration p(50) < 800ms threshold met
A18: 2 | B18: INT-P-002 | C18: Performance / Load | D18: Performance | E18: P1-Critical | F18: k6 load test — p95 < 2000ms | G18: ⬜ NOT RUN | H18: Same as above | I18: Run k6 load-tests/phase0-baseline.js | J18: http_req_duration p(95) < 2000ms threshold met
A19: 3 | B19: INT-P-003 | C19: Performance / Load | D19: Performance | E19: P1-Critical | F19: k6 load test — error rate < 1% | G19: ⬜ NOT RUN | H19: Same as above | I19: Run k6 load-tests/phase0-baseline.js | J19: http_req_failed < 1% threshold met
A20: 4 | B20: INT-P-004 | C20: Performance / Load | D20: Performance | E20: P2-High | F20: Dashboard widgets load independently under load | G20: ⬜ NOT RUN | H20: 100 concurrent users on dashboard | I20: Observe widget load order via browser perf trace | J20: No widget blocks another; each loads within its individual SLA
A21: 5 | B21: INT-P-005 | C21: Performance / Load | D21: Performance | E21: P2-High | F21: 5000 WebSocket connections held without degradation | G21: ⬜ NOT RUN | H21: k6 WebSocket test script | I21: Connect 5000 clients; send heartbeat every 30s for 5 min | J21: All connections maintained; server memory stable; no OOM
A22: Security Baseline
A23: 1 | B23: INT-S-001 | C23: Security Baseline | D23: Security | E23: P1-Critical | F23: Security headers present on all API responses | G23: ⬜ NOT RUN | H23: Playwright security header check | I23: 1. Make GET /auth/me 2. Inspect response headers | J23: X-Content-Type-Options, X-Frame-Options, Strict-Transport-Security, CSP all present
A24: 2 | B24: INT-S-002 | C24: Security Baseline | D24: Security | E24: P1-Critical | F24: JWT uses RS256 (not HS256) | G24: ⬜ NOT RUN | H24: Login and get token | I24: 1. Decode JWT header 2. Check alg field | J24: alg=RS256
A25: 3 | B25: INT-S-003 | C25: Security Baseline | D25: Security | E25: P1-Critical | F25: Rate limiting on /auth/* routes | G25: ⬜ NOT RUN | H25: Unauthenticated client | I25: 1. Send 101 POST /auth/login requests in 60s | J25: 101st request returns 429 Too Many Requests
A26: 4 | B26: INT-S-004 | C26: Security Baseline | D26: Security | E26: P1-Critical | F26: CORS — requests from non-whitelisted origin rejected | G26: ⬜ NOT RUN | H26: API running with ALLOWED_ORIGINS=https://eam.example.com | I26: 1. Make API request with Origin: https://attacker.com | J26: Response has no Access-Control-Allow-Origin header; browser blocks request
